Workbook
Name Average_Selling_Price: Sales!$I$4
Name Total_Purchased_Units: Purchase!$K$3
Name Total_Purchases: Purchase!$K$2
Name Total_Revenue: Sales!$J$2
Name Total_Stock_In: Inventory_Movement!$I$2
Name Total_Stock_Out: Inventory_Movement!$I$3
Name Total_Units_Sold: Sales!$J$3
Name Weekly_Demand_P1: Sales!$K$8:$K$17
Name Weekly_Demand_P15: Sales!$K$30:$K$40
Name Weekly_Demand_P16: Sales!$K$41:$K$52
Name Weekly_Demand_P17: Sales!$K$53
Name Weekly_Demand_P20: Sales!$K$54:$K$61
Name Weekly_Demand_P21: Sales!$K$62:$K$69
Name Weekly_Demand_P23: Sales!$K$70:$K$71
Name Weekly_Demand_P28: Sales!$K$72:$K$80
Name Weekly_Demand_P29: Sales!$K$81:$K$92
Name Weekly_Demand_P32: Sales!$K$93
Name Weekly_Demand_P35: Sales!$K$94:$K$102
Name Weekly_Demand_P37: Sales!$K$103:$K$104
Name Weekly_Demand_P41: Sales!$K$105:$K$106
Name Weekly_Demand_P43: Sales!$K$107
Name Weekly_Demand_P8: Sales!$K$18:$K$29

Sheet Products
A1: Product_ID | B1: Product_Name | C1: Category | D1: Cost_Price | E1: Selling_Price
A2: P001 | B2: Almarai Fresh Milk 1L | C2: Dairy | D2: 4 | E2: 5.75
A3: P002 | B3: Almarai Yogurt 170g | C3: Dairy | D3: 0.9 | E3: 1.5
A4: P003 | B4: Lurpak Butter 200g | C4: Dairy | D4: 7.2 | E4: 9.95
A5: P004 | B5: Kiri Cheese 12 Portions | C5: Dairy | D5: 6.8 | E5: 9.25
A6: P005 | B6: Nadec Labneh 400g | C6: Dairy | D6: 5.5 | E6: 7.5
A7: P006 | B7: Eggs Large 30 Pack | C7: Dairy | D7: 15 | E7: 19.95
A8: P007 | B8: Almarai Cream 200ml | C8: Dairy | D8: 2.8 | E8: 3.95
A9: P008 | B9: Coca Cola 330ml | C9: Beverages | D9: 1.1 | E9: 2
A10: P009 | B10: Pepsi 330ml | C10: Beverages | D10: 1.05 | E10: 2
A11: P010 | B11: Red Bull Energy Drink | C11: Beverages | D11: 5.5 | E11: 7.95
A12: P011 | B12: Masafi Water 1.5L | C12: Beverages | D12: 0.8 | E12: 1.5
A13: P012 | B13: Lipton Ice Tea Lemon | C13: Beverages | D13: 1.4 | E13: 2.5
... A51: P050 | B51: Lux Soap Bar | C51: Personal Care | D51: 1.5 | E51: 2.5

Sheet Cleaned Data
A1: Product_ID | B1: Opening_Stock | G1: Sale_ID | H1: Date | I1: Product_ID | J1: Quantity | K1: Unit_Price | L1: Total_Sales
A2: P001 | B2: 60 | G2: S001 | H2: 45660 | I2: P029 | J2: 12 | K2: 4.95 | L2: 59.4
A3: P002 | B3: 80 | G3: S002 | H3: 45662 | I3: P008 | J3: 24 | K3: 2 | L3: 48
A4: P003 | B4: 50 | G4: S003 | H4: 45663 | I4: P016 | J4: 18 | K4: 3 | L4: 54
A5: P004 | B5: 45 | G5: S004 | H5: 45665 | I5: P001 | J5: 10 | K5: 5.75 | L5: 57.5
A6: P005 | B6: 55 | G6: S005 | H6: 45667 | I6: P020 | J6: 6 | K6: 14.95 | L6: 89.7
A7: P006 | B7: 40 | G7: S006 | H7: 45669 | I7: P015 | J7: 7 | K7: 9.5 | L7: 66.5
A8: P007 | B8: 50 | G8: S007 | H8: 45672 | I8: P035 | J8: 9 | K8: 15.95 | L8: 143.55
A9: P008 | B9: 120 | G9: S008 | H9: 45675 | I9: P041 | J9: 5 | K9: 10.5 | L9: 52.5
A10: P009 | B10: 90 | G10: S009 | H10: 45677 | I10: P028 | J10: 15 | K10: 7.95 | L10: 119.25
A11: P010 | B11: 35 | G11: S010 | H11: 45680 | I11: P021 | J11: 11 | K11: 4.75 | L11: 52.25
A12: P011 | B12: 150 | G12: S011 | H12: 45690 | I12: P016 | J12: 20 | K12: 3 | L12: 60
A13: P012 | B13: 85 | G13: S012 | H13: 45692 | I13: P029 | J13: 14 | K13: 4.95 | L13: 69.3
... A51: P050 | B51: 55 | G51: S050 | H51: 45866 | I51: P020 | J51: 9 | K51: 14.95 | L51: 134.55
G52: S051 | H52: 45871 | I52: P029 | J52: 22 | K52: 4.95 | L52: 108.9
G53: S052 | H53: 45875 | I53: P016 | J53: 30 | K53: 3 | L53: 90
G54: S053 | H54: 45879 | I54: P015 | J54: 15 | K54: 9.5 | L54: 142.5
G55: S054 | H55: 45881 | I55: P028 | J55: 16 | K55: 7.95 | L55: 127.2
A56: PO_ID | B56: Order_Date | C56: Product_ID | D56: Quantity_Ordered | E56: Cost_Price | F56: LeadTime | G56: S055 | H56: 45885 | I56: P001 | J56: 17 | K56: 5.75 | L56: 97.75
A57: PO001 | B57: 45654 | C57: P029 | D57: 200 | E57: 3.2 | F57: 2 | G57: S056 | H57: 45888 | I57: P035 | J57: 13 | K57: 15.95 | L57: 207.35
A58: PO002 | B58: 45654 | C58: P008 | D58: 300 | E58: 1.1 | F58: 3 | G58: S057 | H58: 45892 | I58: P008 | J58: 40 | K58: 2 | L58: 80
A59: PO003 | B59: 45654 | C59: P016 | D59: 180 | E59: 1.8 | F59: 4 | G59: S058 | H59: 45896 | I59: P021 | J59: 16 | K59: 4.75 | L59: 76
A60: PO004 | B60: 45654 | C60: P001 | D60: 120 | E60: 4 | F60: 2 | G60: S059 | H60: 45902 | I60: P029 | J60: 19 | K60: 4.95 | L60: 94.05
A61: PO005 | B61: 45654 | C61: P020 | D61: 90 | E61: 10.5 | F61: 5 | G61: S060 | H61: 45906 | I61: P016 | J61: 26 | K61: 3 | L61: 78
A62: PO006 | B62: 45677 | C62: P015 | D62: 120 | E62: 6 | F62: 4 | G62: S061 | H62: 45910 | I62: P015 | J62: 12 | K62: 9.5 | L62: 114
A63: PO007 | B63: 45693 | C63: P029 | D63: 220 | E63: 3.2 | F63: 2 | G63: S062 | H63: 45914 | I63: P020 | J63: 10 | K63: 14.95 | L63: 149.5
A64: PO008 | B64: 45693 | C64: P016 | D64: 200 | E64: 1.8 | F64: 3 | G64: S063 | H64: 45918 | I64: P028 | J64: 15 | K64: 7.95 | L64: 119.25
A65: PO009 | B65: 45693 | C65: P008 | D65: 350 | E65: 1.1 | F65: 3 | G65: S064 | H65: 45921 | I65: P001 | J65: 14 | K65: 5.75 | L65: 80.5
A66: PO010 | B66: 45717 | C66: P020 | D66: 100 | E66: 10.5 | F66: 5 | G66: S065 | H66: 45925 | I66: P008 | J66: 34 | K66: 2 | L66: 68
A67: PO011 | B67: 45717 | C67: P035 | D67: 80 | E67: 11 | F67: 6 | G67: S066 | H67: 45929 | I67: P021 | J67: 12 | K67: 4.75 | L67: 57
A68: PO012 | B68: 45757 | C68: P029 | D68: 200 | E68: 3.2 | F68: 2 | G68: S067 | H68: 45933 | I68: P029 | J68: 18 | K68: 4.95 | L68: 89.1
... A96: PO040 | B96: 45981 | C96: P035 | D96: 90 | E96: 11 | F96: 6 | G96: S095 | H96: 46019 | I96: P020 | J96: 13 | K96: 14.95 | L96: 194.35
G97: S096 | H97: 46020 | I97: P028 | J97: 20 | K97: 7.95 | L97: 159
G98: S097 | H98: 46021 | I98: P001 | J98: 18 | K98: 5.75 | L98: 103.5
G99: S098 | H99: 46021 | I99: P021 | J99: 17 | K99: 4.75 | L99: 80.75
G100: S099 | H100: 46022 | I100: P035 | J100: 15 | K100: 15.95 | L100: 239.25
G101: S100 | H101: 46022 | I101: P008 | J101: 45 | K101: 2 | L101: 90

Sheet Purchase
A1: PO_ID | B1: Order_Date | C1: Product_ID | D1: Quantity_Ordered | E1: Cost_Price | F1: LeadTime | G1: Total_Purchase_Cos
A2: PO001 | B2: 45654 | C2: P029 | D2: 200 | E2: 3.2 | F2: 2 | G2: 640 | J2: Total Purchases Coast | K2: =SUM(Purchase[Total_Purchase_Cos]) -> 26920
A3: PO002 | B3: 45654 | C3: P008 | D3: 300 | E3: 1.1 | F3: 3 | G3: 330 | J3: Total Purchased Units | K3: =SUM(Purchase[Quantity_Ordered]) -> 6825
A4: PO003 | B4: 45654 | C4: P016 | D4: 180 | E4: 1.8 | F4: 4 | G4: 324
A5: PO004 | B5: 45654 | C5: P001 | D5: 120 | E5: 4 | F5: 2 | G5: 480
A6: PO005 | B6: 45654 | C6: P020 | D6: 90 | E6: 10.5 | F6: 5 | G6: 945
A7: PO006 | B7: 45677 | C7: P015 | D7: 120 | E7: 6 | F7: 4 | G7: 720
A8: PO007 | B8: 45693 | C8: P029 | D8: 220 | E8: 3.2 | F8: 2 | G8: 704
A9: PO008 | B9: 45693 | C9: P016 | D9: 200 | E9: 1.8 | F9: 3 | G9: 360
A10: PO009 | B10: 45693 | C10: P008 | D10: 350 | E10: 1.1 | F10: 3 | G10: 385
A11: PO010 | B11: 45717 | C11: P020 | D11: 100 | E11: 10.5 | F11: 5 | G11: 1050
A12: PO011 | B12: 45717 | C12: P035 | D12: 80 | E12: 11 | F12: 6 | G12: 880
A13: PO012 | B13: 45757 | C13: P029 | D13: 200 | E13: 3.2 | F13: 2 | G13: 640
A14: PO013 | B14: 45757 | C14: P016 | D14: 180 | E14: 1.8 | F14: 3 | G14: 324
A15: PO014 | B15: 45778 | C15: P008 | D15: 320 | E15: 1.1 | F15: 3 | G15: 352
... A41: PO040 | B41: 45981 | C41: P035 | D41: 90 | E41: 11 | F41: 6 | G41: 990

Sheet Opening
A1: Product_ID | B1: Opening_Stock
A2: P001 | B2: 60
A3: P002 | B3: 80
A4: P003 | B4: 50
A5: P004 | B5: 45
A6: P005 | B6: 55
A7: P006 | B7: 40
A8: P007 | B8: 50
A9: P008 | B9: 120
A10: P009 | B10: 90
A11: P010 | B11: 35
A12: P011 | B12: 150
A13: P012 | B13: 85
... A51: P050 | B51: 55

Sheet Inventory_Movement
A1: Product_ID | B1: Opening_Stock | C1: Quantity_in | D1: Quantity_out | E1: Current Stock
A2: P001 | B2: 60 | C2: 120 | D2: 10 | E2: 170 | H2: Total Stock In | I2: =SUM(Inventory_Movement[Quantity_in]) -> 75235
A3: P001 | B3: 60 | C3: 120 | D3: 13 | E3: 167 | H3: Total Stock Out | I3: =SUM(Inventory_Movement[Quantity_out]) -> 8130
A4: P001 | B4: 60 | C4: 120 | D4: 14 | E4: 166
A5: P001 | B5: 60 | C5: 120 | D5: 15 | E5: 165
A6: P001 | B6: 60 | C6: 120 | D6: 17 | E6: 163
A7: P001 | B7: 60 | C7: 120 | D7: 14 | E7: 166
A8: P001 | B8: 60 | C8: 120 | D8: 12 | E8: 168
A9: P001 | B9: 60 | C9: 120 | D9: 13 | E9: 167
A10: P001 | B10: 60 | C10: 110 | D10: 10 | E10: 160
A11: P001 | B11: 60 | C11: 110 | D11: 13 | E11: 157
A12: P001 | B12: 60 | C12: 110 | D12: 14 | E12: 156
A13: P001 | B13: 60 | C13: 110 | D13: 15 | E13: 155
A14: P001 | B14: 60 | C14: 110 | D14: 17 | E14: 153
A15: P001 | B15: 60 | C15: 110 | D15: 14 | E15: 156
... A313: P035 | B313: 55 | C313: 90 | D313: 12 | E313: 133
A314: P041 | B314: 60 | D314: 5
A315: P041 | B315: 60 | D315: 6
A316: P028 | B316: 90 | C316: 150 | D316: 15 | E316: 225
A317: P028 | B317: 90 | C317: 150 | D317: 12 | E317: 228
A318: P028 | B318: 90 | C318: 150 | D318: 14 | E318: 226
A319: P028 | B319: 90 | C319: 150 | D319: 16 | E319: 224
A320: P028 | B320: 90 | C320: 150 | D320: 15 | E320: 225
A321: P028 | B321: 90 | C321: 150 | D321: 13 | E321: 227
A322: P028 | B322: 90 | C322: 150 | D322: 14 | E322: 226
A323: P028 | B323: 90 | C323: 170 | D323: 15 | E323: 245
A324: P028 | B324: 90 | C324: 170 | D324: 12 | E324: 248
A325: P028 | B325: 90 | C325: 170 | D325: 14 | E325: 246
A326: P028 | B326: 90 | C326: 170 | D326: 16 | E326: 244
A327: P028 | B327: 90 | C327: 170 | D327: 15 | E327: 245
... A342: P021 | B342: 60 | C342: 120 | D342: 11 | E342: 169
A343: P023 | B343: 45 | D343: 8
A344: P023 | B344: 45 | D344: 10
A345: P017 | B345: 65 | D345: 15
A346: P037 | B346: 40 | D346: 6
A347: P037 | B347: 40 | D347: 8
A348: P043 | B348: 70 | D348: 7
A349: P032 | B349: 70 | D349: 9
A350: P029 | B350: 100 | C350: 200 | D350: 24 | E350: 276
A351: P029 | B351: 100 | C351: 220 | D351: 24 | E351: 296
...

Sheet Sales
A1: Sale_ID | B1: Date | C1: Week | D1: Product_ID | E1: Quantity | F1: Unit_Price | G1: Total_Sales
A2: S001 | B2: 45660 | C2: 1 | D2: P029 | E2: 12 | F2: 4.95 | G2: 59.4 | I2: Total Revenue | J2: =SUM(Sales[Total_Sales]) -> 9920.8
A3: S002 | B3: 45662 | C3: 2 | D3: P008 | E3: 24 | F3: 2 | G3: 48 | I3: Total Units Sold | J3: =SUM(Sales[Quantity]) -> 1712
A4: S003 | B4: 45663 | C4: 2 | D4: P016 | E4: 18 | F4: 3 | G4: 54 | I4: Average Daily Demand | J4: =Total_Units_Sold/365 -> 4.690411
A5: S004 | B5: 45665 | C5: 2 | D5: P001 | E5: 10 | F5: 5.75 | G5: 57.5
A6: S005 | B6: 45667 | C6: 2 | D6: P020 | E6: 6 | F6: 14.95 | G6: 89.7
A7: S006 | B7: 45669 | C7: 3 | D7: P015 | E7: 7 | F7: 9.5 | G7: 66.5 | I7: Product_ID | J7: Week | K7: Weekly Demand | N7: Product_ID | O7: Average of Weekly Demand
A8: S007 | B8: 45672 | C8: 3 | D8: P035 | E8: 9 | F8: 15.95 | G8: 143.55 | I8: P001 | J8: 2 | K8: 10 | N8: P001 | O8: 14.2
A9: S008 | B9: 45675 | C9: 3 | D9: P041 | E9: 5 | F9: 10.5 | G9: 52.5 | I9: P001 | J9: 10 | K9: 13 | N9: P008 | O9: 34.166667
A10: S009 | B10: 45677 | C10: 4 | D10: P028 | E10: 15 | F10: 7.95 | G10: 119.25 | I10: P001 | J10: 17 | K10: 14 | N10: P015 | O10: 12.818182
A11: S010 | B11: 45680 | C11: 4 | D11: P021 | E11: 11 | F11: 4.75 | G11: 52.25 | I11: P001 | J11: 28 | K11: 15 | N11: P016 | O11: 24.333333
A12: S011 | B12: 45690 | C12: 6 | D12: P016 | E12: 20 | F12: 3 | G12: 60 | I12: P001 | J12: 33 | K12: 17 | N12: P017 | O12: 15
A13: S012 | B13: 45692 | C13: 6 | D13: P029 | E13: 14 | F13: 4.95 | G13: 69.3 | I13: P001 | J13: 39 | K13: 14 | N13: P020 | O13: 9.5
A14: S013 | B14: 45695 | C14: 6 | D14: P008 | E14: 30 | F14: 2 | G14: 60 | I14: P001 | J14: 43 | K14: 12 | N14: P021 | O14: 13.625
A15: S014 | B15: 45699 | C15: 7 | D15: P023 | E15: 8 | F15: 4.5 | G15: 36 | I15: P001 | J15: 48 | K15: 13 | N15: P023 | O15: 9
A16: S015 | B16: 45702 | C16: 7 | D16: P017 | E16: 15 | F16: 2.75 | G16: 41.25 | I16: P001 | J16: 52 | K16: 16 | N16: P028 | O16: 15.222222
A17: S016 | B17: 45706 | C17: 8 | D17: P037 | E17: 6 | F17: 11.5 | G17: 69 | I17: P001 | J17: 53 | K17: 18 | N17: P029 | O17: 18.666667
A18: S017 | B18: 45708 | C18: 8 | D18: P043 | E18: 7 | F18: 5 | G18: 35 | I18: P008 | J18: 2 | K18: 24 | N18: P032 | O18: 9
A19: S018 | B19: 45712 | C19: 9 | D19: P032 | E19: 9 | F19: 8.5 | G19: 76.5 | I19: P008 | J19: 6 | K19: 30 | N19: P035 | O19: 11.888889
... A22: S021 | B22: 45724 | C22: 10 | D22: P001 | E22: 13 | F22: 5.75 | G22: 74.75 | I22: P008 | J22: 25 | K22: 35 | N22: P043 | O22: 7
A23: S022 | B23: 45728 | C23: 11 | D23: P029 | E23: 16 | F23: 4.95 | G23: 79.2 | I23: P008 | J23: 30 | K23: 38
A24: S023 | B24: 45732 | C24: 12 | D24: P008 | E24: 26 | F24: 2 | G24: 52 | I24: P008 | J24: 34 | K24: 40
A25: S024 | B25: 45734 | C25: 12 | D25: P016 | E25: 21 | F25: 3 | G25: 63 | I25: P008 | J25: 39 | K25: 34
A26: S025 | B26: 45738 | C26: 12 | D26: P035 | E26: 10 | F26: 15.95 | G26: 159.5 | I26: P008 | J26: 43 | K26: 32
A27: S026 | B27: 45749 | C27: 14 | D27: P028 | E27: 12 | F27: 7.95 | G27: 95.4 | I27: P008 | J27: 48 | K27: 36
A28: S027 | B28: 45752 | C28: 14 | D28: P015 | E28: 11 | F28: 9.5 | G28: 104.5 | I28: P008 | J28: 52 | K28: 42
A29: S028 | B29: 45755 | C29: 15 | D29: P041 | E29: 6 | F29: 10.5 | G29: 63 | I29: P008 | J29: 53 | K29: 45
A30: S029 | B30: 45757 | C30: 15 | D30: P029 | E30: 15 | F30: 4.95 | G30: 74.25 | I30: P015 | J30: 3 | K30: 7
A31: S030 | B31: 45762 | C31: 16 | D31: P016 | E31: 19 | F31: 3 | G31: 57 | I31: P015 | J31: 10 | K31: 10
A32: S031 | B32: 45767 | C32: 17 | D32: P001 | E32: 14 | F32: 5.75 | G32: 80.5 | I32: P015 | J32: 14 | K32: 11
A33: S032 | B33: 45780 | C33: 18 | D33: P020 | E33: 7 | F33: 14.95 | G33: 104.65 | I33: P015 | J33: 23 | K33: 12
A34: S033 | B34: 45784 | C34: 19 | D34: P008 | E34: 28 | F34: 2 | G34: 56 | I34: P015 | J34: 28 | K34: 13
... A101: S100 | B101: 46022 | C101: 53 | D101: P008 | E101: 45 | F101: 2 | G101: 90 | I101: P035 | J101: 51 | K101: 14
I102: P035 | J102: 53 | K102: 15
I103: P037 | J103: 8 | K103: 6
I104: P037 | J104: 21 | K104: 8
I105: P041 | J105: 3 | K105: 5
I106: P041 | J106: 15 | K106: 6
I107: P043 | J107: 8 | K107: 7
I108: Grand Total | K108: 1712

Sheet Product Analysis
A1: Product_ID | B1: Total Units Sold | C1: Avg Weekly Demand | D1: Std Dev | E1: Lead Time | F1: Safety Stock | G1: ROP
A2: P001 | B2: =SUMIF(Sales[Product_ID],'Product Analysis'!A2,Sales[Quantity]) -> 142 | C2: =INDEX(avg_demand[Average of Weekly Demand],MATCH(Table9[Product_ID],avg_demand[Product_ID])) -> 14.2 | D2: =_xlfn.STDEV.S(Weekly_Demand_P1) -> 2.394438 | E2: =Purchase[LeadTime] -> 2 | F2: =1.65*C2*SQRT(E2) -> 33.135024 | G2: =Table9[Avg Weekly Demand]*Table9[Lead Time]+Table9[Safety Stock] -> 61.535024
A3: P008 | B3: =SUMIF(Sales[Product_ID],'Product Analysis'!A3,Sales[Quantity]) -> 410 | C3: =INDEX(avg_demand[Average of Weekly Demand],MATCH(Table9[Product_ID],avg_demand[Product_ID])) -> 34.166667 | D3: =_xlfn.STDEV.S(Weekly_Demand_P8) -> 6.4784023 | E3: =Purchase[LeadTime] -> 3 | F3: =1.65*C3*SQRT(E3) -> 97.644364 | G3: =Table9[Avg Weekly Demand]*Table9[Lead Time]+Table9[Safety Stock] -> 200.14436
A4: P015 | B4: =SUMIF(Sales[Product_ID],'Product Analysis'!A4,Sales[Quantity]) -> 141 | C4: =INDEX(avg_demand[Average of Weekly Demand],MATCH(Table9[Product_ID],avg_demand[Product_ID])) -> 12.818182 | D4: =_xlfn.STDEV.S(Weekly_Demand_P15) -> 2.9939333 | E4: =Purchase[LeadTime] -> 4 | F4: =1.65*C4*SQRT(E4) -> 42.3 | G4: =Table9[Avg Weekly Demand]*Table9[Lead Time]+Table9[Safety Stock] -> 93.572727
A5: P016 | B5: =SUMIF(Sales[Product_ID],'Product Analysis'!A5,Sales[Quantity]) -> 292 | C5: =INDEX(avg_demand[Average of Weekly Demand],MATCH(Table9[Product_ID],avg_demand[Product_ID])) -> 24.333333 | D5: =_xlfn.STDEV.S(Weekly_Demand_P16) -> 4.2067766 | E5: =Purchase[LeadTime] -> 2 | F5: =1.65*C5*SQRT(E5) -> 56.780675 | G5: =Table9[Avg Weekly Demand]*Table9[Lead Time]+Table9[Safety Stock] -> 105.44734
A6: P017 | B6: =SUMIF(Sales[Product_ID],'Product Analysis'!A6,Sales[Quantity]) -> 15 | C6: =INDEX(avg_demand[Average of Weekly Demand],MATCH(Table9[Product_ID],avg_demand[Product_ID])) -> 15 | D6: 0 | E6: =Purchase[LeadTime] -> 5 | F6: =1.65*C6*SQRT(E6) -> 55.342682 | G6: =Table9[Avg Weekly Demand]*Table9[Lead Time]+Table9[Safety Stock] -> 130.34268
A7: P020 | B7: =SUMIF(Sales[Product_ID],'Product Analysis'!A7,Sales[Quantity]) -> 76 | C7: =INDEX(avg_demand[Average of Weekly Demand],MATCH(Table9[Product_ID],avg_demand[Product_ID])) -> 9.5 | D7: =_xlfn.STDEV.S(Weekly_Demand_P20) -> 2.4494897 | E7: =Purchase[LeadTime] -> 4 | F7: =1.65*C7*SQRT(E7) -> 31.35 | G7: =Table9[Avg Weekly Demand]*Table9[Lead Time]+Table9[Safety Stock] -> 69.35
A8: P021 | B8: =SUMIF(Sales[Product_ID],'Product Analysis'!A8,Sales[Quantity]) -> 109 | C8: =INDEX(avg_demand[Average of Weekly Demand],MATCH(Table9[Product_ID],avg_demand[Product_ID])) -> 13.625 | D8: =_xlfn.STDEV.S(Weekly_Demand_P21) -> 2.2638463 | E8: =Purchase[LeadTime] -> 2 | F8: =1.65*C8*SQRT(E8) -> 31.793289 | G8: =Table9[Avg Weekly Demand]*Table9[Lead Time]+Table9[Safety Stock] -> 59.043289
A9: P023 | B9: =SUMIF(Sales[Product_ID],'Product Analysis'!A9,Sales[Quantity]) -> 18 | C9: =INDEX(avg_demand[Average of Weekly Demand],MATCH(Table9[Product_ID],avg_demand[Product_ID])) -> 9 | D9: =_xlfn.STDEV.S(Weekly_Demand_P23) -> 1.4142136 | E9: =Purchase[LeadTime] -> 3 | F9: =1.65*C9*SQRT(E9) -> 25.720954 | G9: =Table9[Avg Weekly Demand]*Table9[Lead Time]+Table9[Safety Stock] -> 52.720954
A10: P028 | B10: =SUMIF(Sales[Product_ID],'Product Analysis'!A10,Sales[Quantity]) -> 137 | C10: =INDEX(avg_demand[Average of Weekly Demand],MATCH(Table9[Product_ID],avg_demand[Product_ID])) -> 15.222222 | D10: =_xlfn.STDEV.S(Weekly_Demand_P28) -> 2.4888641 | E10: =Purchase[LeadTime] -> 3 | F10: =1.65*C10*SQRT(E10) -> 43.503343 | G10: =Table9[Avg Weekly Demand]*Table9[Lead Time]+Table9[Safety Stock] -> 89.170009
A11: P029 | B11: =SUMIF(Sales[Product_ID],'Product Analysis'!A11,Sales[Quantity]) -> 224 | C11: =INDEX(avg_demand[Average of Weekly Demand],MATCH(Table9[Product_ID],avg_demand[Product_ID])) -> 18.666667 | D11: =_xlfn.STDEV.S(Weekly_Demand_P29) -> 3.9848197 | E11: =Purchase[LeadTime] -> 5 | F11: =1.65*C11*SQRT(E11) -> 68.870894 | G11: =Table9[Avg Weekly Demand]*Table9[Lead Time]+Table9[Safety Stock] -> 162.20423
A12: P032 | B12: =SUMIF(Sales[Product_ID],'Product Analysis'!A12,Sales[Quantity]) -> 9 | C12: =INDEX(avg_demand[Average of Weekly Demand],MATCH(Table9[Product_ID],avg_demand[Product_ID])) -> 9 | D12: 0 | E12: =Purchase[LeadTime] -> 6 | F12: =1.65*C12*SQRT(E12) -> 36.374923 | G12: =Table9[Avg Weekly Demand]*Table9[Lead Time]+Table9[Safety Stock] -> 90.374923
A13: P035 | B13: =SUMIF(Sales[Product_ID],'Product Analysis'!A13,Sales[Quantity]) -> 107 | C13: =INDEX(avg_demand[Average of Weekly Demand],MATCH(Table9[Product_ID],avg_demand[Product_ID])) -> 11.888889 | D13: =_xlfn.STDEV.S(Weekly_Demand_P35) -> 1.9002924 | E13: =Purchase[LeadTime] -> 2 | F13: =1.65*C13*SQRT(E13) -> 27.742156 | G13: =Table9[Avg Weekly Demand]*Table9[Lead Time]+Table9[Safety Stock] -> 51.519934
A14: P037 | B14: =SUMIF(Sales[Product_ID],'Product Analysis'!A14,Sales[Quantity]) -> 14 | C14: =INDEX(avg_demand[Average of Weekly Demand],MATCH(Table9[Product_ID],avg_demand[Product_ID])) -> 7 | D14: =_xlfn.STDEV.S(Weekly_Demand_P37) -> 1.4142136 | E14: =Purchase[LeadTime] -> 3 | F14: =1.65*C14*SQRT(E14) -> 20.005187 | G14: =Table9[Avg Weekly Demand]*Table9[Lead Time]+Table9[Safety Stock] -> 41.005187
A15: P041 | B15: =SUMIF(Sales[Product_ID],'Product Analysis'!A15,Sales[Quantity]) -> 11 | C15: =INDEX(avg_demand[Average of Weekly Demand],MATCH(Table9[Product_ID],avg_demand[Product_ID])) -> 5.5 | D15: =_xlfn.STDEV.S(Weekly_Demand_P41) -> 0.70710678 | E15: =Purchase[LeadTime] -> 3 | F15: =1.65*C15*SQRT(E15) -> 15.718361 | G15: =Table9[Avg Weekly Demand]*Table9[Lead Time]+Table9[Safety Stock] -> 32.218361
A16: P043 | B16: =SUMIF(Sales[Product_ID],'Product Analysis'!A16,Sales[Quantity]) -> 7 | C16: =INDEX(avg_demand[Average of Weekly Demand],MATCH(Table9[Product_ID],avg_demand[Product_ID])) -> 7 | D16: 0 | E16: =Purchase[LeadTime] -> 4 | F16: =1.65*C16*SQRT(E16) -> 23.1 | G16: =Table9[Avg Weekly Demand]*Table9[Lead Time]+Table9[Safety Stock] -> 51.1
